<?xml version="1.0" ?>
<!-- =================================================================================== -->
<!-- |    This document was autogenerated by xacro from quadrupedal_robot2.xacro       | -->
<!-- |    EDITING THIS FILE BY HAND IS NOT RECOMMENDED                                 | -->
<!-- =================================================================================== -->
<robot name="quadrupedal_robot2" xmlns:xacro="https://ros.org/wiki/xacro">
  <!--link name="world"/>
  <joint name="world_joint" type="floating">
		<parent link="world"/>
		<child link="body"/> 
    <origin  rpy="0 0 0" xyz="0 0 0"/>
	</joint-->
  <link name="body">
    <inertial>
      <mass value="3.387196"/>
      <inertia ixx="0.037696260802" ixy="0.0" ixz="0.0" iyy="0.07956409287" iyz="0.0" izz="0.073777565481"/>
    </inertial>
    <visual>
      <geometry>
        <mesh filename="/home/haruki/prog/LeggedRobot/quadrupedal/meshes/stl/body.stl"/>
      </geometry>
    </visual>
    <collision>
      <geometry>
        <mesh filename="/home/haruki/prog/LeggedRobot/quadrupedal/meshes/stl/body.stl"/>
      </geometry>
    </collision>
  </link>
  <gazebo reference="body">
    <mu1 value="1.0"/>
    <mu2 value="2.0"/>
    <kp value="1000000"/>
    <kd value="1.0"/>
    <material>Gazebo/Blue</material>
  </gazebo>
  <joint name="rf_body_joint" type="revolute">
    <parent link="body"/>
    <child link="rf_upper_link"/>
    <axis xyz="0 1 0"/>
    <origin rpy="0.0 0.0 3.14159" xyz="0.19 -0.11 0.06"/>
    <dynamics damping="0.02"/>
    <limit effort="8.0" lower="-2.5" upper="2.5" velocity="6.0"/>
  </joint>
  <transmission name="rf_body_joint_trans">
    <type>transmission_interface/SimpleTransmission</type>
    <joint name="rf_body_joint">
      <hardwareInterface>hardware_interface/EffortJointInterface</hardwareInterface>
    </joint>
    <actuator name="rf_body_motor">
      <hardwareInterface>hardware_interface/EffortJointInterface</hardwareInterface>
      <mechanismReduction>1</mechanismReduction>
    </actuator>
  </transmission>
  <link name="rf_upper_link">
    <inertial>
      <mass value="0.4208"/>
      <inertia ixx="0.002538913384" ixy="0.0" ixz="0.0" iyy="0.002672551616" iyz="0.000139675629" izz="0.000251042991"/>
    </inertial>
    <visual>
      <geometry>
        <mesh filename="/home/haruki/prog/LeggedRobot/quadrupedal/meshes/stl/upper_leg.stl"/>
      </geometry>
    </visual>
    <collision>
      <geometry>
        <mesh filename="/home/haruki/prog/LeggedRobot/quadrupedal/meshes/stl/upper_leg.stl"/>
      </geometry>
    </collision>
  </link>
  <gazebo reference="rf_upper_link">
    <mu1 value="1.0"/>
    <mu2 value="2.0"/>
    <kp value="1000000"/>
    <kd value="1.0"/>
    <material>Gazebo/Red</material>
  </gazebo>
  <joint name="rf_knee_joint" type="revolute">
    <parent link="rf_upper_link"/>
    <child link="rf_under_link"/>
    <axis xyz="0 1 0"/>
    <origin rpy="0.0 0.0 0.0" xyz="0.0 0.0 -0.18"/>
    <dynamics damping="0.02"/>
    <limit effort="8.0" lower="-2.5" upper="2.5" velocity="6.0"/>
  </joint>
  <transmission name="rf_knee_joint_trans">
    <type>transmission_interface/SimpleTransmission</type>
    <joint name="rf_knee_joint">
      <hardwareInterface>hardware_interface/EffortJointInterface</hardwareInterface>
    </joint>
    <actuator name="rf_knee_motor">
      <hardwareInterface>hardware_interface/EffortJointInterface</hardwareInterface>
      <mechanismReduction>1</mechanismReduction>
    </actuator>
  </transmission>
  <link name="rf_under_link">
    <inertial>
      <mass value="0.4208"/>
      <inertia ixx="0.002538913384" ixy="0.0" ixz="0.0" iyy="0.002672551616" iyz="0.000139675629" izz="0.000251042991"/>
    </inertial>
    <visual>
      <geometry>
        <mesh filename="/home/haruki/prog/LeggedRobot/quadrupedal/meshes/stl/under_leg.stl"/>
      </geometry>
    </visual>
    <collision>
      <geometry>
        <mesh filename="/home/haruki/prog/LeggedRobot/quadrupedal/meshes/stl/under_leg.stl"/>
      </geometry>
    </collision>
  </link>
  <gazebo reference="rf_under_link">
    <mu1 value="1.0"/>
    <mu2 value="2.0"/>
    <kp value="1000000"/>
    <kd value="1.0"/>
    <material>Gazebo/Red</material>
  </gazebo>
  <joint name="lf_body_joint" type="revolute">
    <parent link="body"/>
    <child link="lf_upper_link"/>
    <axis xyz="0 1 0"/>
    <origin rpy="0.0 0.0 0.0" xyz="0.19 0.11 0.06"/>
    <dynamics damping="0.02"/>
    <limit effort="8.0" lower="-2.5" upper="2.5" velocity="6.0"/>
  </joint>
  <transmission name="lf_body_joint_trans">
    <type>transmission_interface/SimpleTransmission</type>
    <joint name="lf_body_joint">
      <hardwareInterface>hardware_interface/EffortJointInterface</hardwareInterface>
    </joint>
    <actuator name="lf_body_motor">
      <hardwareInterface>hardware_interface/EffortJointInterface</hardwareInterface>
      <mechanismReduction>1</mechanismReduction>
    </actuator>
  </transmission>
  <link name="lf_upper_link">
    <inertial>
      <mass value="0.4208"/>
      <inertia ixx="0.002538913384" ixy="0.0" ixz="0.0" iyy="0.002672551616" iyz="0.000139675629" izz="0.000251042991"/>
    </inertial>
    <visual>
      <geometry>
        <mesh filename="/home/haruki/prog/LeggedRobot/quadrupedal/meshes/stl/upper_leg.stl"/>
      </geometry>
    </visual>
    <collision>
      <geometry>
        <mesh filename="/home/haruki/prog/LeggedRobot/quadrupedal/meshes/stl/upper_leg.stl"/>
      </geometry>
    </collision>
  </link>
  <gazebo reference="lf_upper_link">
    <mu1 value="1.0"/>
    <mu2 value="2.0"/>
    <kp value="1000000"/>
    <kd value="1.0"/>
    <material>Gazebo/Red</material>
  </gazebo>
  <joint name="lf_knee_joint" type="revolute">
    <parent link="lf_upper_link"/>
    <child link="lf_under_link"/>
    <axis xyz="0 1 0"/>
    <origin rpy="0.0 0.0 0.0" xyz="0.0 0.0 -0.18"/>
    <dynamics damping="0.02"/>
    <limit effort="8.0" lower="-2.5" upper="2.5" velocity="6.0"/>
  </joint>
  <transmission name="lf_knee_joint_trans">
    <type>transmission_interface/SimpleTransmission</type>
    <joint name="lf_knee_joint">
      <hardwareInterface>hardware_interface/EffortJointInterface</hardwareInterface>
    </joint>
    <actuator name="lf_knee_motor">
      <hardwareInterface>hardware_interface/EffortJointInterface</hardwareInterface>
      <mechanismReduction>1</mechanismReduction>
    </actuator>
  </transmission>
  <link name="lf_under_link">
    <inertial>
      <mass value="0.4208"/>
      <inertia ixx="0.002538913384" ixy="0.0" ixz="0.0" iyy="0.002672551616" iyz="0.000139675629" izz="0.000251042991"/>
    </inertial>
    <visual>
      <geometry>
        <mesh filename="/home/haruki/prog/LeggedRobot/quadrupedal/meshes/stl/under_leg.stl"/>
      </geometry>
    </visual>
    <collision>
      <geometry>
        <mesh filename="/home/haruki/prog/LeggedRobot/quadrupedal/meshes/stl/under_leg.stl"/>
      </geometry>
    </collision>
  </link>
  <gazebo reference="lf_under_link">
    <mu1 value="1.0"/>
    <mu2 value="2.0"/>
    <kp value="1000000"/>
    <kd value="1.0"/>
    <material>Gazebo/Red</material>
  </gazebo>
  <joint name="rh_body_joint" type="revolute">
    <parent link="body"/>
    <child link="rh_upper_link"/>
    <axis xyz="0 1 0"/>
    <origin rpy="0.0 0.0 3.14159" xyz="-0.19 -0.11 0.06"/>
    <dynamics damping="0.02"/>
    <limit effort="8.0" lower="-2.5" upper="2.5" velocity="6.0"/>
  </joint>
  <transmission name="rh_body_joint_trans">
    <type>transmission_interface/SimpleTransmission</type>
    <joint name="rh_body_joint">
      <hardwareInterface>hardware_interface/EffortJointInterface</hardwareInterface>
    </joint>
    <actuator name="rh_body_motor">
      <hardwareInterface>hardware_interface/EffortJointInterface</hardwareInterface>
      <mechanismReduction>1</mechanismReduction>
    </actuator>
  </transmission>
  <link name="rh_upper_link">
    <inertial>
      <mass value="0.4208"/>
      <inertia ixx="0.002538913384" ixy="0.0" ixz="0.0" iyy="0.002672551616" iyz="0.000139675629" izz="0.000251042991"/>
    </inertial>
    <visual>
      <geometry>
        <mesh filename="/home/haruki/prog/LeggedRobot/quadrupedal/meshes/stl/upper_leg.stl"/>
      </geometry>
    </visual>
    <collision>
      <geometry>
        <mesh filename="/home/haruki/prog/LeggedRobot/quadrupedal/meshes/stl/upper_leg.stl"/>
      </geometry>
    </collision>
  </link>
  <gazebo reference="rh_upper_link">
    <mu1 value="1.0"/>
    <mu2 value="2.0"/>
    <kp value="1000000"/>
    <kd value="1.0"/>
    <material>Gazebo/Red</material>
  </gazebo>
  <joint name="rh_knee_joint" type="revolute">
    <parent link="rh_upper_link"/>
    <child link="rh_under_link"/>
    <axis xyz="0 1 0"/>
    <origin rpy="0.0 0.0 0.0" xyz="0.0 0.0 -0.18"/>
    <dynamics damping="0.02"/>
    <limit effort="8.0" lower="-2.5" upper="2.5" velocity="6.0"/>
  </joint>
  <transmission name="rh_knee_joint_trans">
    <type>transmission_interface/SimpleTransmission</type>
    <joint name="rh_knee_joint">
      <hardwareInterface>hardware_interface/EffortJointInterface</hardwareInterface>
    </joint>
    <actuator name="rh_knee_motor">
      <hardwareInterface>hardware_interface/EffortJointInterface</hardwareInterface>
      <mechanismReduction>1</mechanismReduction>
    </actuator>
  </transmission>
  <link name="rh_under_link">
    <inertial>
      <mass value="0.4208"/>
      <inertia ixx="0.002538913384" ixy="0.0" ixz="0.0" iyy="0.002672551616" iyz="0.000139675629" izz="0.000251042991"/>
    </inertial>
    <visual>
      <geometry>
        <mesh filename="/home/haruki/prog/LeggedRobot/quadrupedal/meshes/stl/under_leg.stl"/>
      </geometry>
    </visual>
    <collision>
      <geometry>
        <mesh filename="/home/haruki/prog/LeggedRobot/quadrupedal/meshes/stl/under_leg.stl"/>
      </geometry>
    </collision>
  </link>
  <gazebo reference="rh_under_link">
    <mu1 value="1.0"/>
    <mu2 value="2.0"/>
    <kp value="1000000"/>
    <kd value="1.0"/>
    <material>Gazebo/Red</material>
  </gazebo>
  <joint name="lh_body_joint" type="revolute">
    <parent link="body"/>
    <child link="lh_upper_link"/>
    <axis xyz="0 1 0"/>
    <origin rpy="0.0 0.0 0.0" xyz="-0.19 0.11 0.06"/>
    <dynamics damping="0.02"/>
    <limit effort="8.0" lower="-2.5" upper="2.5" velocity="6.0"/>
  </joint>
  <transmission name="lh_body_joint_trans">
    <type>transmission_interface/SimpleTransmission</type>
    <joint name="lh_body_joint">
      <hardwareInterface>hardware_interface/EffortJointInterface</hardwareInterface>
    </joint>
    <actuator name="lh_body_motor">
      <hardwareInterface>hardware_interface/EffortJointInterface</hardwareInterface>
      <mechanismReduction>1</mechanismReduction>
    </actuator>
  </transmission>
  <link name="lh_upper_link">
    <inertial>
      <mass value="0.4208"/>
      <inertia ixx="0.002538913384" ixy="0.0" ixz="0.0" iyy="0.002672551616" iyz="0.000139675629" izz="0.000251042991"/>
    </inertial>
    <visual>
      <geometry>
        <mesh filename="/home/haruki/prog/LeggedRobot/quadrupedal/meshes/stl/upper_leg.stl"/>
      </geometry>
    </visual>
    <collision>
      <geometry>
        <mesh filename="/home/haruki/prog/LeggedRobot/quadrupedal/meshes/stl/upper_leg.stl"/>
      </geometry>
    </collision>
  </link>
  <gazebo reference="lh_upper_link">
    <mu1 value="1.0"/>
    <mu2 value="2.0"/>
    <kp value="1000000"/>
    <kd value="1.0"/>
    <material>Gazebo/Red</material>
  </gazebo>
  <joint name="lh_knee_joint" type="revolute">
    <parent link="lh_upper_link"/>
    <child link="lh_under_link"/>
    <axis xyz="0 1 0"/>
    <origin rpy="0.0 0.0 0.0" xyz="0.0 0.0 -0.18"/>
    <dynamics damping="0.02"/>
    <limit effort="8.0" lower="-2.5" upper="2.5" velocity="6.0"/>
  </joint>
  <transmission name="lh_knee_joint_trans">
    <type>transmission_interface/SimpleTransmission</type>
    <joint name="lh_knee_joint">
      <hardwareInterface>hardware_interface/EffortJointInterface</hardwareInterface>
    </joint>
    <actuator name="lh_knee_motor">
      <hardwareInterface>hardware_interface/EffortJointInterface</hardwareInterface>
      <mechanismReduction>1</mechanismReduction>
    </actuator>
  </transmission>
  <link name="lh_under_link">
    <inertial>
      <mass value="0.4208"/>
      <inertia ixx="0.002538913384" ixy="0.0" ixz="0.0" iyy="0.002672551616" iyz="0.000139675629" izz="0.000251042991"/>
    </inertial>
    <visual>
      <geometry>
        <mesh filename="/home/haruki/prog/LeggedRobot/quadrupedal/meshes/stl/under_leg.stl"/>
      </geometry>
    </visual>
    <collision>
      <geometry>
        <mesh filename="/home/haruki/prog/LeggedRobot/quadrupedal/meshes/stl/under_leg.stl"/>
      </geometry>
    </collision>
  </link>
  <gazebo reference="lh_under_link">
    <mu1 value="1.0"/>
    <mu2 value="2.0"/>
    <kp value="1000000"/>
    <kd value="1.0"/>
    <material>Gazebo/Red</material>
  </gazebo>
</robot>

