<?xml version="1.0" ?>
<!-- =================================================================================== -->
<!-- |    This document was autogenerated by xacro from quadrupedal.xacro              | -->
<!-- |    EDITING THIS FILE BY HAND IS NOT RECOMMENDED                                 | -->
<!-- =================================================================================== -->
<robot name="quadrupedal_robot2" xmlns:xacro="https://ros.org/wiki/xacro">
  <!--link name="world"/>
  <joint name="world_joint" type="floating">
		<parent link="world"/>
		<child link="base"/> 
    <origin  rpy="0 0 0" xyz="0 0 0"/>
	</joint-->
  <link name="base">
    <inertial>
      <origin rpy="0 0 0" xyz="0 0 0"/>
      <mass value="2.792"/>
      <inertia ixx="0.017409405067" ixy="0.0" ixz="0.0" iyy="0.043070296402" iyz="0.0" izz="0.052179256932"/>
    </inertial>
    <visual>
      <geometry>
        <mesh filename="/meshes/stl/base.stl"/>
      </geometry>
    </visual>
    <collision>
      <geometry>
        <mesh filename="/meshes/stl/base.stl"/>
      </geometry>
    </collision>
  </link>
  <gazebo reference="base">
    <mu1 value="1.0"/>
    <mu2 value="2.0"/>
    <kp value="1000000"/>
    <kd value="1.0"/>
    <material>Gazebo/Blue</material>
  </gazebo>
  <joint name="rf_abad_joint" type="revolute">
    <parent link="base"/>
    <child link="rf_abduction_link"/>
    <axis xyz="1 0 0"/>
    <origin rpy="0.0 0.0 0.0" xyz="0.2 -0.11 0.0"/>
    <dynamics damping="0.02"/>
    <limit effort="8.0" lower="-2.5" upper="2.5" velocity="6.0"/>
  </joint>
  <transmission name="rf_abad_joint_trans">
    <type>transmission_interface/SimpleTransmission</type>
    <joint name="rf_abad_joint">
      <hardwareInterface>hardware_interface/EffortJointInterface</hardwareInterface>
    </joint>
    <actuator name="rf_abad_motor">
      <hardwareInterface>hardware_interface/EffortJointInterface</hardwareInterface>
      <mechanismReduction>1</mechanismReduction>
    </actuator>
  </transmission>
  <link name="rf_abduction_link">
    <inertial>
      <origin rpy="0 0 0" xyz="0.0 0.0 0.0"/>
      <mass value="0.0216"/>
      <inertia ixx="9e-07" ixy="0.0" ixz="0.0" iyy="3.6e-06" iyz="0.0" izz="3.06e-06"/>
    </inertial>
    <visual>
      <geometry>
        <mesh filename="/meshes/stl/abduction_link.stl"/>
      </geometry>
    </visual>
    <collision>
      <geometry>
        <mesh filename="/meshes/stl/abduction_link.stl"/>
      </geometry>
    </collision>
  </link>
  <gazebo reference="rf_abduction_link">
    <mu1 value="1.0"/>
    <mu2 value="2.0"/>
    <kp value="1000000"/>
    <kd value="1.0"/>
    <material>Gazebo/Red</material>
  </gazebo>
  <joint name="rf_hip_joint" type="revolute">
    <parent link="rf_abduction_link"/>
    <child link="rf_upper_link"/>
    <axis xyz="0 1 0"/>
    <origin rpy="0.0 0.0 0.0" xyz="0.0 0.0 0.0"/>
    <dynamics damping="0.02"/>
    <limit effort="8.0" lower="-2.5" upper="2.5" velocity="6.0"/>
  </joint>
  <transmission name="rf_hip_joint_trans">
    <type>transmission_interface/SimpleTransmission</type>
    <joint name="rf_hip_joint">
      <hardwareInterface>hardware_interface/EffortJointInterface</hardwareInterface>
    </joint>
    <actuator name="rf_hip_motor">
      <hardwareInterface>hardware_interface/EffortJointInterface</hardwareInterface>
      <mechanismReduction>1</mechanismReduction>
    </actuator>
  </transmission>
  <link name="rf_upper_link">
    <inertial>
      <origin rpy="0 0 0" xyz="0.0 0.0 -0.033267"/>
      <mass value="0.376687"/>
      <inertia ixx="0.001895275931" ixy="0.0" ixz="0.0" iyy="0.002059293642" iyz="0.0" izz="0.00028213453"/>
    </inertial>
    <visual>
      <geometry>
        <mesh filename="/meshes/stl/upper_link.stl"/>
      </geometry>
    </visual>
    <collision>
      <geometry>
        <mesh filename="/meshes/stl/upper_link.stl"/>
      </geometry>
    </collision>
  </link>
  <gazebo reference="rf_upper_link">
    <mu1 value="1.0"/>
    <mu2 value="2.0"/>
    <kp value="1000000"/>
    <kd value="1.0"/>
    <material>Gazebo/Red</material>
  </gazebo>
  <joint name="rf_knee_joint" type="revolute">
    <parent link="rf_upper_link"/>
    <child link="rf_lower_link"/>
    <axis xyz="0 1 0"/>
    <origin rpy="0.0 0.0 0.0" xyz="0.0 0.0 -0.2"/>
    <dynamics damping="0.02"/>
    <limit effort="8.0" lower="-2.5" upper="2.5" velocity="6.0"/>
  </joint>
  <transmission name="rf_knee_joint_trans">
    <type>transmission_interface/SimpleTransmission</type>
    <joint name="rf_knee_joint">
      <hardwareInterface>hardware_interface/EffortJointInterface</hardwareInterface>
    </joint>
    <actuator name="rf_knee_motor">
      <hardwareInterface>hardware_interface/EffortJointInterface</hardwareInterface>
      <mechanismReduction>1</mechanismReduction>
    </actuator>
  </transmission>
  <link name="rf_lower_link">
    <inertial>
      <origin rpy="0 0 0" xyz="0 0 -0.155989"/>
      <mass value="0.140882"/>
      <inertia ixx="0.000664235357" ixy="0.0" ixz="0.0" iyy="0.000664515268" iyz="0.0" izz="1.9650311e-05"/>
    </inertial>
    <visual>
      <geometry>
        <mesh filename="/meshes/stl/lower_link.stl"/>
      </geometry>
    </visual>
    <collision>
      <geometry>
        <mesh filename="/meshes/stl/lower_link.stl"/>
      </geometry>
    </collision>
  </link>
  <gazebo reference="rf_lower_link">
    <mu1 value="1.0"/>
    <mu2 value="2.0"/>
    <kp value="1000000"/>
    <kd value="1.0"/>
    <material>Gazebo/Red</material>
  </gazebo>
  <joint name="lf_abad_joint" type="revolute">
    <parent link="base"/>
    <child link="lf_abduction_link"/>
    <axis xyz="1 0 0"/>
    <origin rpy="0.0 0.0 0.0" xyz="0.2 0.11 0.0"/>
    <dynamics damping="0.02"/>
    <limit effort="8.0" lower="-2.5" upper="2.5" velocity="6.0"/>
  </joint>
  <transmission name="lf_abad_joint_trans">
    <type>transmission_interface/SimpleTransmission</type>
    <joint name="lf_abad_joint">
      <hardwareInterface>hardware_interface/EffortJointInterface</hardwareInterface>
    </joint>
    <actuator name="lf_abad_motor">
      <hardwareInterface>hardware_interface/EffortJointInterface</hardwareInterface>
      <mechanismReduction>1</mechanismReduction>
    </actuator>
  </transmission>
  <link name="lf_abduction_link">
    <inertial>
      <origin rpy="0 0 0" xyz="0.0 0.0 0.0"/>
      <mass value="0.0216"/>
      <inertia ixx="9e-07" ixy="0.0" ixz="0.0" iyy="3.6e-06" iyz="0.0" izz="3.06e-06"/>
    </inertial>
    <visual>
      <geometry>
        <mesh filename="/meshes/stl/abduction_link.stl"/>
      </geometry>
    </visual>
    <collision>
      <geometry>
        <mesh filename="/meshes/stl/abduction_link.stl"/>
      </geometry>
    </collision>
  </link>
  <gazebo reference="lf_abduction_link">
    <mu1 value="1.0"/>
    <mu2 value="2.0"/>
    <kp value="1000000"/>
    <kd value="1.0"/>
    <material>Gazebo/Red</material>
  </gazebo>
  <joint name="lf_hip_joint" type="revolute">
    <parent link="lf_abduction_link"/>
    <child link="lf_upper_link"/>
    <axis xyz="0 1 0"/>
    <origin rpy="0.0 0.0 0.0" xyz="0.0 0.0 0.0"/>
    <dynamics damping="0.02"/>
    <limit effort="8.0" lower="-2.5" upper="2.5" velocity="6.0"/>
  </joint>
  <transmission name="lf_hip_joint_trans">
    <type>transmission_interface/SimpleTransmission</type>
    <joint name="lf_hip_joint">
      <hardwareInterface>hardware_interface/EffortJointInterface</hardwareInterface>
    </joint>
    <actuator name="lf_hip_motor">
      <hardwareInterface>hardware_interface/EffortJointInterface</hardwareInterface>
      <mechanismReduction>1</mechanismReduction>
    </actuator>
  </transmission>
  <link name="lf_upper_link">
    <inertial>
      <origin rpy="0 0 0" xyz="0.0 0.0 -0.033267"/>
      <mass value="0.376687"/>
      <inertia ixx="0.001895275931" ixy="0.0" ixz="0.0" iyy="0.002059293642" iyz="0.0" izz="0.00028213453"/>
    </inertial>
    <visual>
      <geometry>
        <mesh filename="/meshes/stl/upper_link.stl"/>
      </geometry>
    </visual>
    <collision>
      <geometry>
        <mesh filename="/meshes/stl/upper_link.stl"/>
      </geometry>
    </collision>
  </link>
  <gazebo reference="lf_upper_link">
    <mu1 value="1.0"/>
    <mu2 value="2.0"/>
    <kp value="1000000"/>
    <kd value="1.0"/>
    <material>Gazebo/Red</material>
  </gazebo>
  <joint name="lf_knee_joint" type="revolute">
    <parent link="lf_upper_link"/>
    <child link="lf_lower_link"/>
    <axis xyz="0 1 0"/>
    <origin rpy="0.0 0.0 0.0" xyz="0.0 0.0 -0.2"/>
    <dynamics damping="0.02"/>
    <limit effort="8.0" lower="-2.5" upper="2.5" velocity="6.0"/>
  </joint>
  <transmission name="lf_knee_joint_trans">
    <type>transmission_interface/SimpleTransmission</type>
    <joint name="lf_knee_joint">
      <hardwareInterface>hardware_interface/EffortJointInterface</hardwareInterface>
    </joint>
    <actuator name="lf_knee_motor">
      <hardwareInterface>hardware_interface/EffortJointInterface</hardwareInterface>
      <mechanismReduction>1</mechanismReduction>
    </actuator>
  </transmission>
  <link name="lf_lower_link">
    <inertial>
      <origin rpy="0 0 0" xyz="0 0 -0.155989"/>
      <mass value="0.140882"/>
      <inertia ixx="0.000664235357" ixy="0.0" ixz="0.0" iyy="0.000664515268" iyz="0.0" izz="1.9650311e-05"/>
    </inertial>
    <visual>
      <geometry>
        <mesh filename="/meshes/stl/lower_link.stl"/>
      </geometry>
    </visual>
    <collision>
      <geometry>
        <mesh filename="/meshes/stl/lower_link.stl"/>
      </geometry>
    </collision>
  </link>
  <gazebo reference="lf_lower_link">
    <mu1 value="1.0"/>
    <mu2 value="2.0"/>
    <kp value="1000000"/>
    <kd value="1.0"/>
    <material>Gazebo/Red</material>
  </gazebo>
  <joint name="rh_abad_joint" type="revolute">
    <parent link="base"/>
    <child link="rh_abduction_link"/>
    <axis xyz="1 0 0"/>
    <origin rpy="0.0 0.0 0.0" xyz="-0.2 -0.11 0.0"/>
    <dynamics damping="0.02"/>
    <limit effort="8.0" lower="-2.5" upper="2.5" velocity="6.0"/>
  </joint>
  <transmission name="rh_abad_joint_trans">
    <type>transmission_interface/SimpleTransmission</type>
    <joint name="rh_abad_joint">
      <hardwareInterface>hardware_interface/EffortJointInterface</hardwareInterface>
    </joint>
    <actuator name="rh_abad_motor">
      <hardwareInterface>hardware_interface/EffortJointInterface</hardwareInterface>
      <mechanismReduction>1</mechanismReduction>
    </actuator>
  </transmission>
  <link name="rh_abduction_link">
    <inertial>
      <origin rpy="0 0 0" xyz="0.0 0.0 0.0"/>
      <mass value="0.0216"/>
      <inertia ixx="9e-07" ixy="0.0" ixz="0.0" iyy="3.6e-06" iyz="0.0" izz="3.06e-06"/>
    </inertial>
    <visual>
      <geometry>
        <mesh filename="/meshes/stl/abduction_link.stl"/>
      </geometry>
    </visual>
    <collision>
      <geometry>
        <mesh filename="/meshes/stl/abduction_link.stl"/>
      </geometry>
    </collision>
  </link>
  <gazebo reference="rh_abduction_link">
    <mu1 value="1.0"/>
    <mu2 value="2.0"/>
    <kp value="1000000"/>
    <kd value="1.0"/>
    <material>Gazebo/Red</material>
  </gazebo>
  <joint name="rh_hip_joint" type="revolute">
    <parent link="rh_abduction_link"/>
    <child link="rh_upper_link"/>
    <axis xyz="0 1 0"/>
    <origin rpy="0.0 0.0 0.0" xyz="0.0 0.0 0.0"/>
    <dynamics damping="0.02"/>
    <limit effort="8.0" lower="-2.5" upper="2.5" velocity="6.0"/>
  </joint>
  <transmission name="rh_hip_joint_trans">
    <type>transmission_interface/SimpleTransmission</type>
    <joint name="rh_hip_joint">
      <hardwareInterface>hardware_interface/EffortJointInterface</hardwareInterface>
    </joint>
    <actuator name="rh_hip_motor">
      <hardwareInterface>hardware_interface/EffortJointInterface</hardwareInterface>
      <mechanismReduction>1</mechanismReduction>
    </actuator>
  </transmission>
  <link name="rh_upper_link">
    <inertial>
      <origin rpy="0 0 0" xyz="0.0 0.0 -0.033267"/>
      <mass value="0.376687"/>
      <inertia ixx="0.001895275931" ixy="0.0" ixz="0.0" iyy="0.002059293642" iyz="0.0" izz="0.00028213453"/>
    </inertial>
    <visual>
      <geometry>
        <mesh filename="/meshes/stl/upper_link.stl"/>
      </geometry>
    </visual>
    <collision>
      <geometry>
        <mesh filename="/meshes/stl/upper_link.stl"/>
      </geometry>
    </collision>
  </link>
  <gazebo reference="rh_upper_link">
    <mu1 value="1.0"/>
    <mu2 value="2.0"/>
    <kp value="1000000"/>
    <kd value="1.0"/>
    <material>Gazebo/Red</material>
  </gazebo>
  <joint name="rh_knee_joint" type="revolute">
    <parent link="rh_upper_link"/>
    <child link="rh_lower_link"/>
    <axis xyz="0 1 0"/>
    <origin rpy="0.0 0.0 0.0" xyz="0.0 0.0 -0.2"/>
    <dynamics damping="0.02"/>
    <limit effort="8.0" lower="-2.5" upper="2.5" velocity="6.0"/>
  </joint>
  <transmission name="rh_knee_joint_trans">
    <type>transmission_interface/SimpleTransmission</type>
    <joint name="rh_knee_joint">
      <hardwareInterface>hardware_interface/EffortJointInterface</hardwareInterface>
    </joint>
    <actuator name="rh_knee_motor">
      <hardwareInterface>hardware_interface/EffortJointInterface</hardwareInterface>
      <mechanismReduction>1</mechanismReduction>
    </actuator>
  </transmission>
  <link name="rh_lower_link">
    <inertial>
      <origin rpy="0 0 0" xyz="0 0 -0.155989"/>
      <mass value="0.140882"/>
      <inertia ixx="0.000664235357" ixy="0.0" ixz="0.0" iyy="0.000664515268" iyz="0.0" izz="1.9650311e-05"/>
    </inertial>
    <visual>
      <geometry>
        <mesh filename="/meshes/stl/lower_link.stl"/>
      </geometry>
    </visual>
    <collision>
      <geometry>
        <mesh filename="/meshes/stl/lower_link.stl"/>
      </geometry>
    </collision>
  </link>
  <gazebo reference="rh_lower_link">
    <mu1 value="1.0"/>
    <mu2 value="2.0"/>
    <kp value="1000000"/>
    <kd value="1.0"/>
    <material>Gazebo/Red</material>
  </gazebo>
  <joint name="lh_abad_joint" type="revolute">
    <parent link="base"/>
    <child link="lh_abduction_link"/>
    <axis xyz="1 0 0"/>
    <origin rpy="0.0 0.0 0.0" xyz="-0.2 0.11 0.0"/>
    <dynamics damping="0.02"/>
    <limit effort="8.0" lower="-2.5" upper="2.5" velocity="6.0"/>
  </joint>
  <transmission name="lh_abad_joint_trans">
    <type>transmission_interface/SimpleTransmission</type>
    <joint name="lh_abad_joint">
      <hardwareInterface>hardware_interface/EffortJointInterface</hardwareInterface>
    </joint>
    <actuator name="lh_abad_motor">
      <hardwareInterface>hardware_interface/EffortJointInterface</hardwareInterface>
      <mechanismReduction>1</mechanismReduction>
    </actuator>
  </transmission>
  <link name="lh_abduction_link">
    <inertial>
      <origin rpy="0 0 0" xyz="0.0 0.0 0.0"/>
      <mass value="0.0216"/>
      <inertia ixx="9e-07" ixy="0.0" ixz="0.0" iyy="3.6e-06" iyz="0.0" izz="3.06e-06"/>
    </inertial>
    <visual>
      <geometry>
        <mesh filename="/meshes/stl/abduction_link.stl"/>
      </geometry>
    </visual>
    <collision>
      <geometry>
        <mesh filename="/meshes/stl/abduction_link.stl"/>
      </geometry>
    </collision>
  </link>
  <gazebo reference="lh_abduction_link">
    <mu1 value="1.0"/>
    <mu2 value="2.0"/>
    <kp value="1000000"/>
    <kd value="1.0"/>
    <material>Gazebo/Red</material>
  </gazebo>
  <joint name="lh_hip_joint" type="revolute">
    <parent link="lh_abduction_link"/>
    <child link="lh_upper_link"/>
    <axis xyz="0 1 0"/>
    <origin rpy="0.0 0.0 0.0" xyz="0.0 0.0 0.0"/>
    <dynamics damping="0.02"/>
    <limit effort="8.0" lower="-2.5" upper="2.5" velocity="6.0"/>
  </joint>
  <transmission name="lh_hip_joint_trans">
    <type>transmission_interface/SimpleTransmission</type>
    <joint name="lh_hip_joint">
      <hardwareInterface>hardware_interface/EffortJointInterface</hardwareInterface>
    </joint>
    <actuator name="lh_hip_motor">
      <hardwareInterface>hardware_interface/EffortJointInterface</hardwareInterface>
      <mechanismReduction>1</mechanismReduction>
    </actuator>
  </transmission>
  <link name="lh_upper_link">
    <inertial>
      <origin rpy="0 0 0" xyz="0.0 0.0 -0.033267"/>
      <mass value="0.376687"/>
      <inertia ixx="0.001895275931" ixy="0.0" ixz="0.0" iyy="0.002059293642" iyz="0.0" izz="0.00028213453"/>
    </inertial>
    <visual>
      <geometry>
        <mesh filename="/meshes/stl/upper_link.stl"/>
      </geometry>
    </visual>
    <collision>
      <geometry>
        <mesh filename="/meshes/stl/upper_link.stl"/>
      </geometry>
    </collision>
  </link>
  <gazebo reference="lh_upper_link">
    <mu1 value="1.0"/>
    <mu2 value="2.0"/>
    <kp value="1000000"/>
    <kd value="1.0"/>
    <material>Gazebo/Red</material>
  </gazebo>
  <joint name="lh_knee_joint" type="revolute">
    <parent link="lh_upper_link"/>
    <child link="lh_lower_link"/>
    <axis xyz="0 1 0"/>
    <origin rpy="0.0 0.0 0.0" xyz="0.0 0.0 -0.2"/>
    <dynamics damping="0.02"/>
    <limit effort="8.0" lower="-2.5" upper="2.5" velocity="6.0"/>
  </joint>
  <transmission name="lh_knee_joint_trans">
    <type>transmission_interface/SimpleTransmission</type>
    <joint name="lh_knee_joint">
      <hardwareInterface>hardware_interface/EffortJointInterface</hardwareInterface>
    </joint>
    <actuator name="lh_knee_motor">
      <hardwareInterface>hardware_interface/EffortJointInterface</hardwareInterface>
      <mechanismReduction>1</mechanismReduction>
    </actuator>
  </transmission>
  <link name="lh_lower_link">
    <inertial>
      <origin rpy="0 0 0" xyz="0 0 -0.155989"/>
      <mass value="0.140882"/>
      <inertia ixx="0.000664235357" ixy="0.0" ixz="0.0" iyy="0.000664515268" iyz="0.0" izz="1.9650311e-05"/>
    </inertial>
    <visual>
      <geometry>
        <mesh filename="/meshes/stl/lower_link.stl"/>
      </geometry>
    </visual>
    <collision>
      <geometry>
        <mesh filename="/meshes/stl/lower_link.stl"/>
      </geometry>
    </collision>
  </link>
  <gazebo reference="lh_lower_link">
    <mu1 value="1.0"/>
    <mu2 value="2.0"/>
    <kp value="1000000"/>
    <kd value="1.0"/>
    <material>Gazebo/Red</material>
  </gazebo>
</robot>

